Workbook
Name Argentina: 'Reference data'!$D$61:$D$61
Name Brazil: 'Reference data'!$D$62:$D$63
Name Bulgaria: 'Reference data'!$D$64:$D$66
Name Cambodia: 'Reference data'!$D$67:$D$71
Name Chile: 'Reference data'!$D$72:$D$73
Name Colombia: 'Reference data'!$D$74:$D$76
Name Costa_Rica: 'Reference data'!$D$77:$D$78
Name Customer: 'Reference data'!$D$79
Name Hungary: 'Reference data'!$D$80:$D$80
Name India: 'Reference data'!$D$81:$D$87
Name Latvia: 'Reference data'!$D$88:$D$91
Name Lithuania: 'Reference data'!$D$92:$D$95
Name Malaysia: 'Reference data'!$D$96:$D$102
Name Myanmar: 'Reference data'!#REF!
Name Performer_Country: 'Reference data'!$D$4:$D$21
Name Peru: 'Reference data'!$D$103:$D$104
Name Philippines: 'Reference data'!$D$105:$D$108
Name Thailand: 'Reference data'!$D$109:$D$109
Name Vietnam: 'Reference data'!$D$110:$D$115

Sheet !FAQ
A1: Q: What is the purpose of this file and how I should use it? (please, read me first!)
A2: A: This is a template to help you estimate delivery expenses and project cost for services projects. File contains all important variables to account necessary cost items into project cost. File contains three sheets to gradually lead you through project cost estimation. 1. Start from "Project overview" sheet to fill details about customer, project, requirements and pre-sale team. 2. Once done, move forward with effort estimations on sheet "Project estimations_adv". Specify scope of work, select proper resources, estimate tasks by man manhours and risks, select required percentage of architect and project manager involvement, put partner cost if necessary. If you need to overview the resources total man hours and cost by roles you may switch to the "Resources overview" sheet. 3. Once you complete estimations, go back to the sheet "Project overview" to finalize the key project parameters: project scope and timeline, additional expenses. Check project budget, commercials, choose required margin level and review recommended project price. All sheets in the file are designed with the same colour approach:
B3: Fields where you input is required are pink colored;
B4: Fields where values are automatically calculated have grey color. Please do not make any changes in these fields.
A6: Q: How should I estimate project duration?
A7: A: To estimate project duration definition of the project scope is required: you need to understand which tasks or stages will be performed one by one, and which can be done in parallel. Based on that you will be able to estimate project duration. For project duration estimation we recommend to use consideration as 1 day = 6 engineer hours. This is because engineer should have some time availabe during the day for pre-sale, learning and some internal activities. If you're unsure about project duration estimation you may ask project manager to help. Example: let's say we have a total estimations for project = 80 hours with 4 stages in scope. Each stage will take 20 hours to be completed. Stages 1, 2, 3 should be done one by one, but stage 4 will be done in parallel with stage 3 (second engineer will participate). Thus, our duration will be 20 hours * 3 time stages = 60 hours / 6 hours a day = 10 business days.
A9: Q: What is the difference between simple and advanced estimations template?
A10: A: 2.1 Simple estimations template is recommended to use for typical projects up to 15.000$. Your estimations in this case come from initial understanding of approximate cost of the project and previous experience. Using this template you may estimate efforts by stages in man days. 2.2 Advanced estimations template is recommended for custom project with cost > 15.000$. In this case you probably don't know the project cost at the beginning and your estimations will be prepared through thinking about necessary tasks and efforts required for each of them.

Sheet 2a.Travel calc
A1: Travel expenses calculator
B2: Customer name | C2: =IF(ISBLANK(V_Customer),"",V_Customer) -> #NAME? | F2: Date | G2: 43413
B3: Project name | C3: =IF(ISBLANK(V_ProjectName),"",V_ProjectName) -> #NAME? | F3: Prepared by
A5: Fill only fields like | C5: Yellow
B6: From | C6: Russia
B7: To | C7: Malaysia
A9: № | B9: Expense | C9: Category | D9: Value
A10: 1 | B10: Total working hours to be spent onsite | D10: 0
A11: 2 | B11: Number of persons in the business trip | D11: 1
A12: 3 | B12: Total working days in the buisiness trip for 1 person | D12: =ROUNDUP(D10/8/D11,0) -> 0
A13: 4 | B13: Per diems | D13: =INDEX(#REF!,MATCH('2a.Travel calc'!C6,#REF!,0),MATCH('2a.Travel calc'!C7,#REF!,0)) -> #REF!
A14: 5 | B14: Accommodation expenses | C14: INT_Category 1 | D14: =VLOOKUP(C14,#REF!,2,FALSE) -> #REF!
A15: 6 | B15: Round trip tickets (train, avia, etc) | D15: 1000
A16: 7 | B16: Project manager trips for onsite kick-offs and other meetings | C16: 0 | D16: 2
A17: 8 | B17: Other travel expenses * | D17: 0
A18: 9 | B18: Reserve for not identified risks ** | D18: 0.1
A20: Total buisiness trip expenses, $ | D20: =((1.4*(IF(D12>15,D12/ROUNDUP(D12/15,0),D12)*(D13+D14))+D15)*ROUNDUP(D12/15,0)*D11+(1.4*D16*(D13+D14)+D15)*C16)*(100%+D18)+D17 -> #REF!
B22: * - Other travel expenses includes: - Train to/from airport expenses - Taxi expenses - Purchase of consumables for a project needs - Car rent - Other expenses | C22: ** - Not identified risks includes: - Trip tickets value changes - Additional transport expenses and taxes - Unplanned taxi expenses in the case of force majeure - Additional airport/railway station rates and taxes - Other unplanned expenses (В случае вопросов по данному пункту уточните у Руководителя проекта)

Sheet PM-PA catalog
A1: Project Management Cost Calculator
A3: Performed measures | B3: Labor costs, h | C3: Quantity | D3: Total, h | E3: Notes
A4: Project initiation
A5: Analysis of the input data, the acceptance of the project from the Solution Sale | B5: 1 | C5: 1 | D5: =B5*C5 -> 1 | E5: one-time
A6: Estimate man-hours on project management, calculate business trips and other expenses, risks reservation | B6: 2 | C6: 1 | D6: =B6*C6 -> 2 | E6: one-time
A7: Preparing project plan with timelines (depending of project duration) | B7: 1 | C7: 1 | D7: =B7*C7 -> 1 | E7: one-time
A8: Preparing initial list of risks with action plan for each | B8: 2 | C8: 1 | D8: =B8*C8 -> 2 | E8: one-time
A9: Prepare (and agree on) spending budget of the project and cash flow plan | B9: 2 | C9: 1 | D9: =B9*C9 -> 2 | E9: one-time
A10: Filling in the FS, negotiating the contract with the customer | B10: 2 | C10: 1 | D10: =B10*C10 -> 2 | E10: one-time
A11: Project accounting in corporate information systems
A12: Creating an estimate in 1C | B12: 0 | C12: 1 | D12: =B12*C12 -> 0 | E12: one-time
A13: Creating a Project Plan on Project Server | B13: 1 | C13: 1 | D13: =B13*C13 -> 1 | E13: one-time
A14: Creation of a project card and communication plan in CRM | B14: 0 | C14: 1 | D14: =B14*C14 -> 0 | E14: one-time
A15: Audit of the project start stage | B15: 0 | C15: 1 | D15: =B15*C15 -> 0 | E15: one-time
A16: Project start
A17: Formation of the project team | B17: 2 | C17: 1 | D17: =B17*C17 -> 2 | E17: one-time
A18: Formation of project documentation | B18: 0 | C18: 1 | D18: =B18*C18 -> 0 | E18: one-time
A19: Internal installation meeting (+ protocol) | B19: 2 | C19: 1 | D19: =B19*C19 -> 2 | E19: one-time
A20: External installation meeting (+ protocol) | B20: 2 | C20: 1 | D20: =B20*C20 -> 2 | E20: one-time
A21: Setting tasks, starting work | B21: 1 | C21: 1 | D21: =B21*C21 -> 1 | E21: one-time
A22: Work with subcontractors
A23: Search and attraction of subcontractors, meetings and discussions | B23: 1 | C23: =IF(#REF!="Yes",1,0) -> #REF! | D23: =B23*C23 -> #REF! | E23: one-time, by the number of contractors
A24: Execution of an application for a subcontractor | B24: 1 | C24: =IF(#REF!="Yes",1,0) -> #REF! | D24: =B24*C24 -> #REF! | E24: one-time, by the number of contractors
A25: Alignment of the contract with the subcontractor | B25: 2 | C25: =IF(#REF!="Yes",1,0) -> #REF! | D25: =B25*C25 -> #REF! | E25: one-time, by the number of contractors
A26: Installation meeting, setting tasks | B26: 1 | C26: =IF(#REF!="Yes",1,0) -> #REF! | D26: =B26*C26 -> #REF! | E26: one-time, by the number of contractors
A27: Monitoring and control
A28: Internal discussion of the status of the project, informing | B28: 1 | C28: =#REF! -> #REF! | D28: =B28*C28 -> #REF! | E28: weekly
A29: External discussion of the status of the project, informing | B29: 1 | C29: =#REF! -> #REF! | D29: =B29*C29 -> #REF! | E29: weekly
A30: Solving operational issues with the project team | B30: 1 | C30: =#REF! -> #REF! | D30: =B30*C30 -> #REF! | E30: weekly
A31: Solving operational issues with the customer | B31: 1 | C31: =#REF! -> #REF! | D31: =B31*C31 -> #REF! | E31: weekly
A32: Risk management | B32: 1 | C32: =#REF! -> #REF! | D32: =B32*C32 -> #REF! | E32: weekly
A33: Updating the project plan, recording labor costs | B33: 1 | C33: =#REF! -> #REF! | D33: =B33*C33 -> #REF! | E33: weekly
A34: Hardware logistics control | B34: 1 | C34: =IF(V_IsLogistics="Yes",#REF!,0) -> #NAME? | D34: =B34*C34 -> #NAME? | E34: weekly
A35: Project handover
A36: Acceptance of works from subcontractors | B36: 2 | C36: =V_IsSubContractor -> #NAME? | D36: =B36*C36 -> #NAME? | E36: one-time (for each subcontractor)
A37: Execution of acceptance and transfer acts of works with a subcontractor | B37: 1 | C37: =V_IsSubContractor -> #NAME? | D37: =B37*C37 -> #NAME? | E37: one-time (for each subcontractor)
A38: Payment for subcontractor's works, making applications in 1C | B38: 0.5 | C38: =V_IsSubContractor -> #NAME? | D38: =B38*C38 -> #NAME? | E38: one-time (for each subcontractor)
A39: Participation in the UAT | B39: 2 | C39: 1 | D39: =B39*C39 -> 2 | E39: one-time
A40: Registration of documents and delivery to the customer | B40: 2 | C40: =IF(V_HoursTechWriter>0,1,0) -> #NAME? | D40: =B40*C40 -> #NAME? | E40: one-time
A41: Execution of acceptance and transfer acts of works with a customer | B41: 2 | C41: 1 | D41: =B41*C41 -> 2 | E41: one-time
...

Sheet Project overview
B2: Pre-sale team
B3: Account manager | C3: Put account manager's name here
B4: Solution sales | C4: Put solution sales name here
B5: Delivery | C5: Put the name of the one who are estimating the project effort
B6: Project manager | C6: Put project manager name here
B7: [Add more roles if needed] | C7: Add more lines if needed and specify the roles and names
B9: Customer details
B10: Cutomer name | C10: Put customer name here
B11: Customer country
B12: CRM opportunity ID | C12: Indicate CRM opportunity which is related to given estimation
B14: Project details
B15: Project name | C15: Put project name here
B16: Project objectives | C16: Describe the goals and objectives of the potential project, associated business problem and other important details referring project purpose
B18: Project high-level requrements
B19: Project funding source | C19: Describe the revenue streams (customer budget, vendor funding etc.) and specify expected revenue amount from each of them
B20: Summary available project funding, USD | C20: Input the total available sum to fund turn-key solution implementation (services and any required software/hardware)
B21: Customer's requirements and expectations | C21: Describe customer requirements which given project should address (technical, organizational, time-related, financial and any others). Mention everything which may affect project scope, budget, timeline, techical methodolody and approach to project management.
B23: ! IMPORTANT ! Key project parameters below should be treated as delivery commitments for a project. They should become the basis of the commercial and technical proposal for the customer.
B24: Project scope
B25: Project scope | C25: Describe key deliverables and specify if anything is out of scope
B26: Project constraints | C26: Describe any constraints that should be agreed with the customer and included into proposal
B27: Internal requirements | C27: Any specific internal requirements for the project
B29: Project timeline
B30: Project timeline | C30: Specify estimated project implementation time | E30: Enter value
B32: Project expenditure budget
B33: In-house delivery resources | C33: ='Project estimations_adv'!I29 -> 2613.6 | E33: Refer to Estimations - A
B34: Assessed risks | C34: ='Project estimations_adv'!I38 -> 0 | E34: Refer to Estimations - B
B35: 3rd parties/ partners | C35: ='Project estimations_adv'!I47 -> 0 | E35: Refer to Estimations - C
B36: Project management | C36: ='Project estimations_adv'!I56 -> 24.948 | E36: Refer to Estimations - D
B37: Business trips | C37: 0 | E37: Enter value
B38: Consumables | C38: 0 | E38: Enter value
B39: Other expenses | C39: 0 | E39: Enter value
B40: TOTAL PROJECT COST/ BUDGET | C40: =SUM(C33:C39) -> 2638.548 | E40: Calculation
B42: Commercials
B43: Target margin | C43: 0.3 | E43: Enter value
B44: Gross profit | C44: =C45-C40 -> 1130.8063 | E44: Calculation
B45: TOTAL PROJECT PRICE (REVENUE) | C45: =C40/(1-C43) -> 3769.3543 | E45: Calculation
B47: Potential contract price
B48: Services revenue | C48: =C45 -> 3769.3543 | E48: Calculation
B49: Licence revenue (reference) | E49: Enter value
...

Sheet Project estimations_adv
J1: Target margin (refer to Project overview)
C2: A. In-house delivery resources | J2: ='Project overview'!C43 -> 0.3
C4: # | D4: Project implementation tasks | E4: Resource country | F4: Resource role | G4: Rate, USD | H4: Estimated hours | I4: Cost, USD | J4: Revenue, USD | K4: Resource Full Name
C5: 1 | D5: Requirements & Sample Data Alignment | E5: Malaysia | F5: Engineer | G5: =IFERROR(VLOOKUP(Table_SOW[[#This Row],[Resource country]]&Table_SOW[[#This Row],[Resource role]],Table_Rates[#All],4,FALSE),"n/a") -> 22 | H5: 4 | I5: =IFERROR(Table_SOW[[#This Row],[Rate, USD]]*Table_SOW[[#This Row],[Estimated hours]],"Check role") -> 88 | J5: =IFERROR(Table_SOW[[#This Row],[Cost, USD]]/(1-'Project overview'!$C$43),"Check role") -> 125.71429 | K5: =CONCATENATE(Table_SOW[[#This Row],[Resource country]]," ",Table_SOW[[#This Row],[Resource role]]) -> Malaysia Engineer
C6: 2 | D6: Azure AI Infrastructure Provisioning | E6: Malaysia | F6: Engineer | G6: =IFERROR(VLOOKUP(Table_SOW[[#This Row],[Resource country]]&Table_SOW[[#This Row],[Resource role]],Table_Rates[#All],4,FALSE),"n/a") -> 22 | H6: 4 | I6: =IFERROR(Table_SOW[[#This Row],[Rate, USD]]*Table_SOW[[#This Row],[Estimated hours]],"Check role") -> 88 | J6: =IFERROR(Table_SOW[[#This Row],[Cost, USD]]/(1-'Project overview'!$C$43),"Check role") -> 125.71429 | K6: =CONCATENATE(Table_SOW[[#This Row],[Resource country]]," ",Table_SOW[[#This Row],[Resource role]]) -> Malaysia Engineer
C7: 3 | D7: M365 & Power Platform Environment Setup | E7: Malaysia | F7: Engineer | G7: =IFERROR(VLOOKUP(Table_SOW[[#This Row],[Resource country]]&Table_SOW[[#This Row],[Resource role]],Table_Rates[#All],4,FALSE),"n/a") -> 22 | H7: 8 | I7: =IFERROR(Table_SOW[[#This Row],[Rate, USD]]*Table_SOW[[#This Row],[Estimated hours]],"Check role") -> 176 | J7: =IFERROR(Table_SOW[[#This Row],[Cost, USD]]/(1-'Project overview'!$C$43),"Check role") -> 251.42857 | K7: =CONCATENATE(Table_SOW[[#This Row],[Resource country]]," ",Table_SOW[[#This Row],[Resource role]]) -> Malaysia Engineer
C8: 4 | D8: Dataverse Schema & Mock Ledgers | E8: Malaysia | F8: Engineer | G8: =IFERROR(VLOOKUP(Table_SOW[[#This Row],[Resource country]]&Table_SOW[[#This Row],[Resource role]],Table_Rates[#All],4,FALSE),"n/a") -> 22 | H8: 8 | I8: =IFERROR(Table_SOW[[#This Row],[Rate, USD]]*Table_SOW[[#This Row],[Estimated hours]],"Check role") -> 176 | J8: =IFERROR(Table_SOW[[#This Row],[Cost, USD]]/(1-'Project overview'!$C$43),"Check role") -> 251.42857 | K8: =CONCATENATE(Table_SOW[[#This Row],[Resource country]]," ",Table_SOW[[#This Row],[Resource role]]) -> Malaysia Engineer
C9: 5 | D9: OCR Model Calibration | E9: Malaysia | F9: Engineer | G9: =IFERROR(VLOOKUP(Table_SOW[[#This Row],[Resource country]]&Table_SOW[[#This Row],[Resource role]],Table_Rates[#All],4,FALSE),"n/a") -> 22 | H9: 8 | I9: =IFERROR(Table_SOW[[#This Row],[Rate, USD]]*Table_SOW[[#This Row],[Estimated hours]],"Check role") -> 176 | J9: =IFERROR(Table_SOW[[#This Row],[Cost, USD]]/(1-'Project overview'!$C$43),"Check role") -> 251.42857 | K9: =CONCATENATE(Table_SOW[[#This Row],[Resource country]]," ",Table_SOW[[#This Row],[Resource role]]) -> Malaysia Engineer
C10: 6 | D10: GPT-4o Vision Prompt Engineering | E10: Malaysia | F10: Engineer | G10: =IFERROR(VLOOKUP(Table_SOW[[#This Row],[Resource country]]&Table_SOW[[#This Row],[Resource role]],Table_Rates[#All],4,FALSE),"n/a") -> 22 | H10: 8 | I10: =IFERROR(Table_SOW[[#This Row],[Rate, USD]]*Table_SOW[[#This Row],[Estimated hours]],"Check role") -> 176 | J10: =IFERROR(Table_SOW[[#This Row],[Cost, USD]]/(1-'Project overview'!$C$43),"Check role") -> 251.42857 | K10: =CONCATENATE(Table_SOW[[#This Row],[Resource country]]," ",Table_SOW[[#This Row],[Resource role]]) -> Malaysia Engineer
C11: 7 | D11: Process 1 Power Automate Workflows - Build RFP Ingestion | E11: Malaysia | F11: Engineer | G11: =IFERROR(VLOOKUP(Table_SOW[[#This Row],[Resource country]]&Table_SOW[[#This Row],[Resource role]],Table_Rates[#All],4,FALSE),"n/a") -> 22 | H11: 12 | I11: =IFERROR(Table_SOW[[#This Row],[Rate, USD]]*Table_SOW[[#This Row],[Estimated hours]],"Check role") -> 264 | J11: =IFERROR(Table_SOW[[#This Row],[Cost, USD]]/(1-'Project overview'!$C$43),"Check role") -> 377.14286 | K11: =CONCATENATE(Table_SOW[[#This Row],[Resource country]]," ",Table_SOW[[#This Row],[Resource role]]) -> Malaysia Engineer
C12: 8 | D12: Process 2 Power Automate Workflows - Build Document Intelligence | E12: Malaysia | F12: Engineer | G12: =IFERROR(VLOOKUP(Table_SOW[[#This Row],[Resource country]]&Table_SOW[[#This Row],[Resource role]],Table_Rates[#All],4,FALSE),"n/a") -> 22 | H12: 12 | I12: =IFERROR(Table_SOW[[#This Row],[Rate, USD]]*Table_SOW[[#This Row],[Estimated hours]],"Check role") -> 264 | J12: =IFERROR(Table_SOW[[#This Row],[Cost, USD]]/(1-'Project overview'!$C$43),"Check role") -> 377.14286 | K12: =CONCATENATE(Table_SOW[[#This Row],[Resource country]]," ",Table_SOW[[#This Row],[Resource role]]) -> Malaysia Engineer
C13: 9 | D13: Teams Adaptive Cards (v1.5) Development | E13: Malaysia | F13: Engineer | G13: =IFERROR(VLOOKUP(Table_SOW[[#This Row],[Resource country]]&Table_SOW[[#This Row],[Resource role]],Table_Rates[#All],4,FALSE),"n/a") -> 22 | H13: 8 | I13: =IFERROR(Table_SOW[[#This Row],[Rate, USD]]*Table_SOW[[#This Row],[Estimated hours]],"Check role") -> 176 | J13: =IFERROR(Table_SOW[[#This Row],[Cost, USD]]/(1-'Project overview'!$C$43),"Check role") -> 251.42857 | K13: =CONCATENATE(Table_SOW[[#This Row],[Resource country]]," ",Table_SOW[[#This Row],[Resource role]]) -> Malaysia Engineer
C14: 10 | D14: Copilot Studio Agent Orchestration | E14: Malaysia | F14: Engineer | G14: =IFERROR(VLOOKUP(Table_SOW[[#This Row],[Resource country]]&Table_SOW[[#This Row],[Resource role]],Table_Rates[#All],4,FALSE),"n/a") -> 22 | H14: 16 | I14: =IFERROR(Table_SOW[[#This Row],[Rate, USD]]*Table_SOW[[#This Row],[Estimated hours]],"Check role") -> 352 | J14: =IFERROR(Table_SOW[[#This Row],[Cost, USD]]/(1-'Project overview'!$C$43),"Check role") -> 502.85714 | K14: =CONCATENATE(Table_SOW[[#This Row],[Resource country]]," ",Table_SOW[[#This Row],[Resource role]]) -> Malaysia Engineer
C15: 11 | D15: End-to-End System Testing & Tuning | E15: Malaysia | F15: Engineer | G15: =IFERROR(VLOOKUP(Table_SOW[[#This Row],[Resource country]]&Table_SOW[[#This Row],[Resource role]],Table_Rates[#All],4,FALSE),"n/a") -> 22 | H15: 8 | I15: =IFERROR(Table_SOW[[#This Row],[Rate, USD]]*Table_SOW[[#This Row],[Estimated hours]],"Check role") -> 176 | J15: =IFERROR(Table_SOW[[#This Row],[Cost, USD]]/(1-'Project overview'!$C$43),"Check role") -> 251.42857 | K15: =CONCATENATE(Table_SOW[[#This Row],[Resource country]]," ",Table_SOW[[#This Row],[Resource role]]) -> Malaysia Engineer
C16: 12 | D16: Strategy & Assessment Collateral | E16: Malaysia | F16: Engineer | G16: =IFERROR(VLOOKUP(Table_SOW[[#This Row],[Resource country]]&Table_SOW[[#This Row],[Resource role]],Table_Rates[#All],4,FALSE),"n/a") -> 22 | H16: 4 | I16: =IFERROR(Table_SOW[[#This Row],[Rate, USD]]*Table_SOW[[#This Row],[Estimated hours]],"Check role") -> 88 | J16: =IFERROR(Table_SOW[[#This Row],[Cost, USD]]/(1-'Project overview'!$C$43),"Check role") -> 125.71429 | K16: =CONCATENATE(Table_SOW[[#This Row],[Resource country]]," ",Table_SOW[[#This Row],[Resource role]]) -> Malaysia Engineer
C17: 13 | D17: Internal Freeze, Video Recording & Executive Dry Run | E17: Malaysia | F17: Engineer | G17: =IFERROR(VLOOKUP(Table_SOW[[#This Row],[Resource country]]&Table_SOW[[#This Row],[Resource role]],Table_Rates[#All],4,FALSE),"n/a") -> 22 | H17: 8 | I17: =IFERROR(Table_SOW[[#This Row],[Rate, USD]]*Table_SOW[[#This Row],[Estimated hours]],"Check role") -> 176 | J17: =IFERROR(Table_SOW[[#This Row],[Cost, USD]]/(1-'Project overview'!$C$43),"Check role") -> 251.42857 | K17: =CONCATENATE(Table_SOW[[#This Row],[Resource country]]," ",Table_SOW[[#This Row],[Resource role]]) -> Malaysia Engineer
G18: =IFERROR(VLOOKUP(Table_SOW[[#This Row],[Resource country]]&Table_SOW[[#This Row],[Resource role]],Table_Rates[#All],4,FALSE),"n/a") -> n/a | I18: =IFERROR(Table_SOW[[#This Row],[Rate, USD]]*Table_SOW[[#This Row],[Estimated hours]],"Check role") -> Check role | J18: =IFERROR(Table_SOW[[#This Row],[Cost, USD]]/(1-'Project overview'!$C$43),"Check role") -> Check role | K18: =CONCATENATE(Table_SOW[[#This Row],[Resource country]]," ",Table_SOW[[#This Row],[Resource role]])
G19: =IFERROR(VLOOKUP(Table_SOW[[#This Row],[Resource country]]&Table_SOW[[#This Row],[Resource role]],Table_Rates[#All],4,FALSE),"n/a") -> n/a | I19: =IFERROR(Table_SOW[[#This Row],[Rate, USD]]*Table_SOW[[#This Row],[Estimated hours]],"Check role") -> Check role | J19: =IFERROR(Table_SOW[[#This Row],[Cost, USD]]/(1-'Project overview'!$C$43),"Check role") -> Check role | K19: =CONCATENATE(Table_SOW[[#This Row],[Resource country]]," ",Table_SOW[[#This Row],[Resource role]])
G20: =IFERROR(VLOOKUP(Table_SOW[[#This Row],[Resource country]]&Table_SOW[[#This Row],[Resource role]],Table_Rates[#All],4,FALSE),"n/a") -> n/a | I20: =IFERROR(Table_SOW[[#This Row],[Rate, USD]]*Table_SOW[[#This Row],[Estimated hours]],"Check role") -> Check role | J20: =IFERROR(Table_SOW[[#This Row],[Cost, USD]]/(1-'Project overview'!$C$43),"Check role") -> Check role | K20: =CONCATENATE(Table_SOW[[#This Row],[Resource country]]," ",Table_SOW[[#This Row],[Resource role]])
C21: Total | H21: =SUBTOTAL(109,Table_SOW[Estimated hours]) -> 108 | I21: =SUBTOTAL(109,Table_SOW[Cost, USD]) -> 2376 | J21: =SUBTOTAL(109,Table_SOW[Revenue, USD]) -> 3394.2857
B23: Estimation accuracy buffer | D23: Select appropriate value of the correction level depending of the assumption of the estimation accuracy level, supposition of not assessible risks and other unseen circumstances . This will be added on top of the resource cost as a buffer. | I23: Cost, USD | J23: Revenue, USD
B24: 0.1 | I24: =Table_SOW[[#Totals],[Cost, USD]]*B24 -> 237.6 | J24: =I24/(1-'Project overview'!$C$43) -> 339.42857
B26: Technical governance - Project architect involvement ratio | D26: Estimate overall involvement ratio in %, then choose the approproate role, so this will be applied to overall in-house cost, and estimated hours will be calculated automatically. | E26: Resource country | F26: Resource role | G26: Rate, USD | H26: Estimated hours | I26: Cost, USD | J26: Revenue, USD
B27: 0.1 | G27: =IF(E27="",0,VLOOKUP(E27&F27,Table_Rates[#All],4,FALSE)) -> 0 | H27: =Table_SOW[[#Totals],[Estimated hours]]*B27 -> 10.8 | I27: =G27*H27 -> 0 | J27: =I27/(1-'Project overview'!$C$43) -> 0 | L27: =IF(ISERROR(G27),"Calculation is not correct, check resource role and rate!"," ")
F29: Total cost of in-house delivery resources | I29: =Table_SOW[[#Totals],[Cost, USD]]+I27+I24 -> 2613.6 | J29: =Table_SOW[[#Totals],[Revenue, USD]]+J27+J24 -> 3733.7143
B31: B. Assessed risks
B33: # | C33: Risk name | D33: Risk description | E33: Risk level | F33: Strategy | I33: Cost, USD | J33: Revenue, USD
B34: 1 | C34: Risk #1 | D34: Describe the essense of the risk end it's potential effect | E34: High | F34: Define the strategy to work with the risk (avoidance, mitigation, transfer, acceptance) and describe required actions | I34: 0 | J34: =I34/(1-'Project overview'!$C$43) -> 0
B35: 2 | C35: Risk #2 | E35: Medium | I35: 0 | J35: =I35/(1-'Project overview'!$C$43) -> 0
B36: 3 | C36: Risk #3 | E36: Low | I36: 0 | J36: =I36/(1-'Project overview'!$C$43) -> 0
F38: Total assesed risks cost | I38: =SUM(I34:I36) -> 0 | J38: =SUM(J34:J36) -> 0
B40: C. 3rd parties/ partners
B42: # | C42: Subcontractor | D42: Involvement reason | E42: Scope | I42: Cost, USD | J42: Revenue, USD
B43: 1 | C43: Name #1 | D43: Specify the need of given engagament (lack of in-house expertise, certain accreditation is required, cost effectiveness, customer requirement, etc.) | E43: Specify the project scope/ deliverables entrusted to execute by 3rd party | J43: =I43/(1-'Project overview'!$C$43) -> 0
B44: 2 | C44: Name #2 | D44: Specify the need of given engagament (lack of in-house expertise, certain accreditation is required, cost effectiveness, customer requirement, etc.) | E44: Specify the project scope/ deliverables entrusted to execute by 3rd party | I44: 0 | J44: =I44/(1-'Project overview'!$C$43) -> 0
B45: 3 | C45: Name #3 | D45: Specify the need of given engagament (lack of in-house expertise, certain accreditation is required, cost effectiveness, customer requirement, etc.) | E45: Specify the project scope/ deliverables entrusted to execute by 3rd party | I45: 0 | J45: =I45/(1-'Project overview'!$C$43) -> 0
F47: Total subcontactors cost | I47: =SUM(I43:I45) -> 0 | J47: =SUM(J43:J45) -> 0
B51: D. Project management | F51: Subtotal for calculate project management cost | I51: =I29+I38+I47 -> 2613.6 | J51: =J29+J38+J47 -> 3733.7143
B53: Project management - PM involvement ratio | D53: Estimate overall involvement ratio in %, then choose the approproate role, so this will be applied to overall in-house cost, and estimated hours will be calculated automatically. | E53: Resource country | F53: Resource role | G53: Rate, USD | H53: Estimated hours | I53: Cost, USD | J53: Revenue, USD
B54: 0.1 | G54: =IF(E54="",0.1,VLOOKUP(E54&F54,Table_Rates[#All],4,FALSE)) -> 0.1 | H54: =((Table_SOW[[#Totals],[Estimated hours]]+H27)*B54)+(B54*(I24+I38+I47))/G54 -> 249.48 | I54: =G54*H54 -> 24.948 | J54: =I54/(1-'Project overview'!$C$43) -> 35.64 | L54: =IF(ISERROR(G54),"Calculation is not correct, check resource role and rate!"," ")
...

Sheet Resources overview
A1: Project governance overview
A2: Role | B2: Total man hours | C2: Total cost
A3: =CONCATENATE('Project estimations_adv'!E27," ",'Project estimations_adv'!F27) | B3: ='Project estimations_adv'!H27 -> 10.8 | C3: ='Project estimations_adv'!I27 -> 0
A4: =CONCATENATE('Project estimations_adv'!E54," ",'Project estimations_adv'!F54) | B4: ='Project estimations_adv'!H54 -> 249.48 | C4: ='Project estimations_adv'!I54 -> 24.948
A5: Total | B5: =B3+B4 -> 260.28 | C5: =C3+C4 -> 24.948
A7: Project delivery overview
A8: Role | B8: Total man hours | C8: Total cost
C9: 0
A10: Malaysia Engineer | B10: 108 | C10: 2376
A11: Total | B11: 108 | C11: 2376 | D11: Right-click on table and "Refresh" to refresh the data

Sheet Reference data
B3: Country | D3: Performer country
B4: Argentina | D4: Argentina
B5: Brazil | D5: Brazil
B6: Bulgaria | D6: Bulgaria
B7: Cambodia | D7: Cambodia
B8: Chile | D8: Chile
B9: Colombia | D9: Colombia
B10: Costa Rica | D10: Costa_Rica
B11: Croatia | D11: Customer
B12: Ecuador | D12: Hungary
B13: Egypt | D13: India
B14: El Salvador | D14: Latvia
... B21: Lithuania | D21: Vietnam
B22: Malaysia
B23: Mexico
B24: Myanmar
B25: Nicaragua
B26: Thailand
B27: Panama
B28: Paraguay
B29: Peru
B30: Philippines
B31: Romania
B32: Serbia
B33: Slovakia
... B58: Teamlead
B60: Rate name | C60: Country | D60: Role | E60: Hour rate, USD
B61: =_xlfn.CONCAT(Table_Rates[[#This Row],[Country]],Table_Rates[[#This Row],[Role]]) -> ArgentinaEngineer | C61: Argentina | D61: Engineer | E61: 31
B62: =_xlfn.CONCAT(Table_Rates[[#This Row],[Country]],Table_Rates[[#This Row],[Role]]) -> BrazilEngineer | C62: Brazil | D62: Engineer | E62: 31
B63: =_xlfn.CONCAT(Table_Rates[[#This Row],[Country]],Table_Rates[[#This Row],[Role]]) -> BrazilProject manager | C63: Brazil | D63: Project manager | E63: 29
B64: =_xlfn.CONCAT(Table_Rates[[#This Row],[Country]],Table_Rates[[#This Row],[Role]]) -> BulgariaArchitect | C64: Bulgaria | D64: Architect | E64: 75
B65: =_xlfn.CONCAT(Table_Rates[[#This Row],[Country]],Table_Rates[[#This Row],[Role]]) -> BulgariaSenior engineer | C65: Bulgaria | D65: Senior engineer | E65: 58
B66: =_xlfn.CONCAT(Table_Rates[[#This Row],[Country]],Table_Rates[[#This Row],[Role]]) -> BulgariaProject manager | C66: Bulgaria | D66: Project manager | E66: 63
B67: =_xlfn.CONCAT(Table_Rates[[#This Row],[Country]],Table_Rates[[#This Row],[Role]]) -> CambodiaJunior engineer | C67: Cambodia | D67: Junior engineer | E67: 8
B68: =_xlfn.CONCAT(Table_Rates[[#This Row],[Country]],Table_Rates[[#This Row],[Role]]) -> CambodiaEngineer | C68: Cambodia | D68: Engineer | E68: 15
B69: =_xlfn.CONCAT(Table_Rates[[#This Row],[Country]],Table_Rates[[#This Row],[Role]]) -> CambodiaArchitect | C69: Cambodia | D69: Architect | E69: 51
B70: =_xlfn.CONCAT(Table_Rates[[#This Row],[Country]],Table_Rates[[#This Row],[Role]]) -> CambodiaProject coordinator | C70: Cambodia | D70: Project coordinator | E70: 21
B71: =_xlfn.CONCAT(Table_Rates[[#This Row],[Country]],Table_Rates[[#This Row],[Role]]) -> CambodiaSenior engineer | C71: Cambodia | D71: Senior engineer | E71: 26
B72: =_xlfn.CONCAT(Table_Rates[[#This Row],[Country]],Table_Rates[[#This Row],[Role]]) -> ChileEngineer | C72: Chile | D72: Engineer | E72: 31
... B115: =_xlfn.CONCAT(Table_Rates[[#This Row],[Country]],Table_Rates[[#This Row],[Role]]) -> VietnamSupport engineer | C115: Vietnam | D115: Support engineer | E115: 15

Sheet reference
A2: Requirement source | C2: Priority | E2: Author | G2: Complexity | I2: Relevance | K2: Project direction | M2: Industry
A3: Softline | C3: High | E3: Requirements management analyst | G3: High | I3: Actual | K3: Antivirus protection | M3: Automotive industry
A4: Customer | C4: Medium | E4: Pre-sale architect | G4: Medium | I4: Not actual | K4: Informatization objects attestation | M4: Gas industry
C5: Low | E5: Project architect | G5: Low | K5: Audit of computing / network infrastructure | M5: State and municipal sector
E6: Customer | K6: Audit for compliance with information security requirements | M6: Housing and utilities
E7: Engineer | K7: Virtualization (Vmware and Microsoft) | M7: Healthcare
E8: Consultant | K8: Virtual Desktops Ingfrastructure (VDI) | M8: Information Technology
E9: Project manager | K9: DLP implementing | M9: Light industry
K10: IDM implementing | M10: Mechanical engineering
K11: SIEM implementing | M11: Metallurgy
K12: WAF / DBF implementing | M12: Science and scientific services
E13: Delivery roles | K13: Information security management system implementing | M13: Oil-producing industry
E14: Engineer | K14: CIP implementing | M14: Oil refining industry
E15: Analyst | K15: Delivering applications and balancers | M15: Education
E16: Consultant | K16: State secrets protection | M16: Food industry
E17: Technical Writer | K17: Information protectiob in Banking Organizations | M17: Instrument making
E18: Technical Architect | K18: Trade secret protection | M18: Project institutes
E19: Customer | K19: Personal data protection | M19: Restaurants and catering
K20: Microsoft Infrastructure | M20: Agriculture
K21: Complex Infrastructure Projects | M21: Mass media
K22: Comprehensive information security projects | M22: Construction, real estate
K23: Content filtering | M23: Trade
K24: Provision the security of information in the process control system | M24: Transport
K25: Provision the activity of the certifying center (CA) | M25: Tourism
K26: Business continuity provisioning | M26: Coal industry
K27: Cloud technologies | M27: Pharmaceuticals
K28: Portal solutions | M28: Finance, credit, insurance, pensions
K29: Mail systems | M29: Chemical and petrochemical industry
K30: Countering DDOS attacks | M30: Electrotechnical industry
K31: Backup | M31: Power engineering
K32: Servers and storage | M32: Jurisprudence
K33: Network Security
K34: Networks - Routing & Switching
K35: Networks - Unified Communications
K36: Networks - Wireless
K37: Business Intelligence Systems (BI)
K38: Management systems
K39: Database management systems
K40: IT Service Management (ITSM)
K41: Corporate Content Management (ECM)
